2025-08-15 14:22:17,965 INFO    MainThread:100979 [wandb_setup.py:_flush():80] Current SDK version is 0.21.1
2025-08-15 14:22:17,966 INFO    MainThread:100979 [wandb_setup.py:_flush():80] Configure stats pid to 100979
2025-08-15 14:22:17,966 INFO    MainThread:100979 [wandb_setup.py:_flush():80] Loading settings from /root/.config/wandb/settings
2025-08-15 14:22:17,969 INFO    MainThread:100979 [wandb_setup.py:_flush():80] Loading settings from /workspace/volume/gxs2/zht/project4/QW3/RAG/wandb/settings
2025-08-15 14:22:17,969 INFO    MainThread:100979 [wandb_setup.py:_flush():80] Loading settings from environment variables
2025-08-15 14:22:17,971 INFO    MainThread:100979 [wandb_init.py:setup_run_log_directory():703] Logging user logs to /workspace/volume/gxs2/zht/project4/QW3/RAG/wandb/run-20250815_142217-h31ku025/logs/debug.log
2025-08-15 14:22:17,973 INFO    MainThread:100979 [wandb_init.py:setup_run_log_directory():704] Logging internal logs to /workspace/volume/gxs2/zht/project4/QW3/RAG/wandb/run-20250815_142217-h31ku025/logs/debug-internal.log
2025-08-15 14:22:17,975 INFO    MainThread:100979 [wandb_init.py:init():830] calling init triggers
2025-08-15 14:22:17,975 INFO    MainThread:100979 [wandb_init.py:init():835] wandb.init called with sweep_config: {}
config: {'_wandb': {}}
2025-08-15 14:22:17,977 INFO    MainThread:100979 [wandb_init.py:init():871] starting backend
2025-08-15 14:22:18,189 INFO    MainThread:100979 [wandb_init.py:init():874] sending inform_init request
2025-08-15 14:22:18,194 INFO    MainThread:100979 [wandb_init.py:init():882] backend started and connected
2025-08-15 14:22:18,196 INFO    MainThread:100979 [wandb_init.py:init():953] updated telemetry
2025-08-15 14:22:18,197 INFO    MainThread:100979 [wandb_init.py:init():977] communicating run to backend with 90.0 second timeout
2025-08-15 14:22:49,045 INFO    Thread-3 (wrapped_target):100979 [retry.py:__call__():173] [no run ID] Retry attempt failed:
Traceback (most recent call last):
  File "/torch/venv3/pytorch/lib/python3.10/site-packages/urllib3/connection.py", line 174, in _new_conn
    conn = connection.create_connection(
  File "/torch/venv3/pytorch/lib/python3.10/site-packages/urllib3/util/connection.py", line 95, in create_connection
    raise err
  File "/torch/venv3/pytorch/lib/python3.10/site-packages/urllib3/util/connection.py", line 85, in create_connection
    sock.connect(sa)
TimeoutError: timed out

During handling of the above exception, another exception occurred:

Traceback (most recent call last):
  File "/torch/venv3/pytorch/lib/python3.10/site-packages/urllib3/connectionpool.py", line 716, in urlopen
    httplib_response = self._make_request(
  File "/torch/venv3/pytorch/lib/python3.10/site-packages/urllib3/connectionpool.py", line 404, in _make_request
    self._validate_conn(conn)
  File "/torch/venv3/pytorch/lib/python3.10/site-packages/urllib3/connectionpool.py", line 1061, in _validate_conn
    conn.connect()
  File "/torch/venv3/pytorch/lib/python3.10/site-packages/urllib3/connection.py", line 363, in connect
    self.sock = conn = self._new_conn()
  File "/torch/venv3/pytorch/lib/python3.10/site-packages/urllib3/connection.py", line 179, in _new_conn
    raise ConnectTimeoutError(
urllib3.exceptions.ConnectTimeoutError: (<urllib3.connection.HTTPSConnection object at 0x7f63580421a0>, 'Connection to api.wandb.ai timed out. (connect timeout=20)')

During handling of the above exception, another exception occurred:

Traceback (most recent call last):
  File "/torch/venv3/pytorch/lib/python3.10/site-packages/requests/adapters.py", line 489, in send
    resp = conn.urlopen(
  File "/torch/venv3/pytorch/lib/python3.10/site-packages/urllib3/connectionpool.py", line 802, in urlopen
    retries = retries.increment(
  File "/torch/venv3/pytorch/lib/python3.10/site-packages/urllib3/util/retry.py", line 594, in increment
    raise MaxRetryError(_pool, url, error or ResponseError(cause))
urllib3.exceptions.MaxRetryError: HTTPSConnectionPool(host='api.wandb.ai', port=443): Max retries exceeded with url: /graphql (Caused by ConnectTimeoutError(<urllib3.connection.HTTPSConnection object at 0x7f63580421a0>, 'Connection to api.wandb.ai timed out. (connect timeout=20)'))

During handling of the above exception, another exception occurred:

Traceback (most recent call last):
  File "/torch/venv3/pytorch/lib/python3.10/site-packages/wandb/sdk/lib/retry.py", line 134, in __call__
    result = self._call_fn(*args, **kwargs)
  File "/torch/venv3/pytorch/lib/python3.10/site-packages/wandb/sdk/internal/internal_api.py", line 398, in execute
    return self.client.execute(*args, **kwargs)  # type: ignore
  File "/torch/venv3/pytorch/lib/python3.10/site-packages/wandb/vendor/gql-0.2.0/wandb_gql/client.py", line 52, in execute
    result = self._get_result(document, *args, **kwargs)
  File "/torch/venv3/pytorch/lib/python3.10/site-packages/wandb/vendor/gql-0.2.0/wandb_gql/client.py", line 60, in _get_result
    return self.transport.execute(document, *args, **kwargs)
  File "/torch/venv3/pytorch/lib/python3.10/site-packages/wandb/sdk/lib/gql_request.py", line 58, in execute
    request = self.session.post(self.url, **post_args)
  File "/torch/venv3/pytorch/lib/python3.10/site-packages/requests/sessions.py", line 635, in post
    return self.request("POST", url, data=data, json=json, **kwargs)
  File "/torch/venv3/pytorch/lib/python3.10/site-packages/requests/sessions.py", line 587, in request
    resp = self.send(prep, **send_kwargs)
  File "/torch/venv3/pytorch/lib/python3.10/site-packages/requests/sessions.py", line 701, in send
    r = adapter.send(request, **kwargs)
  File "/torch/venv3/pytorch/lib/python3.10/site-packages/requests/adapters.py", line 553, in send
    raise ConnectTimeout(e, request=request)
requests.exceptions.ConnectTimeout: HTTPSConnectionPool(host='api.wandb.ai', port=443): Max retries exceeded with url: /graphql (Caused by ConnectTimeoutError(<urllib3.connection.HTTPSConnection object at 0x7f63580421a0>, 'Connection to api.wandb.ai timed out. (connect timeout=20)'))
2025-08-15 14:23:18,244 WARNING MainThread:100979 [wandb_init.py:init():1585] [no run ID] interrupted
Traceback (most recent call last):
  File "/torch/venv3/pytorch/lib/python3.10/site-packages/wandb/sdk/wandb_init.py", line 1581, in init
    return wi.init(run_settings, run_config, run_printer)
  File "/torch/venv3/pytorch/lib/python3.10/site-packages/wandb/sdk/wandb_init.py", line 996, in init
    result = wait_with_progress(
  File "/torch/venv3/pytorch/lib/python3.10/site-packages/wandb/sdk/mailbox/wait_with_progress.py", line 24, in wait_with_progress
    return wait_all_with_progress(
  File "/torch/venv3/pytorch/lib/python3.10/site-packages/wandb/sdk/mailbox/wait_with_progress.py", line 87, in wait_all_with_progress
    return asyncio_compat.run(progress_loop_with_timeout)
  File "/torch/venv3/pytorch/lib/python3.10/site-packages/wandb/sdk/lib/asyncio_compat.py", line 30, in run
    return future.result()
  File "/opt/py3.10/lib/python3.10/concurrent/futures/_base.py", line 453, in result
    self._condition.wait(timeout)
  File "/opt/py3.10/lib/python3.10/threading.py", line 320, in wait
    waiter.acquire()
KeyboardInterrupt
2025-08-15 14:23:19,251 INFO    MsgRouterThr:100979 [mailbox.py:close():129] [no run ID] Closing mailbox, abandoning 2 handles.
